2023-07-23 23:05:44,045 INFO: Memateka startup [in D:\Projects\python\control_system_database_mems\app\__init__.py:52]
2023-07-23 23:05:48,146 ERROR: Exception on /meme/2 [GET] [in D:\Projects\python\control_system_database_mems\venv\lib\site-packages\flask\app.py:1457]
Traceback (most recent call last):
  File "D:\Projects\python\control_system_database_mems\venv\lib\site-packages\sqlalchemy\engine\base.py", line 1802, in _execute_context
    self.dialect.do_execute(
  File "D:\Projects\python\control_system_database_mems\venv\lib\site-packages\sqlalchemy\engine\default.py", line 732, in do_execute
    cursor.execute(statement, parameters)
psycopg2.errors.UndefinedTable: relation "account" does not exist
LINE 2: FROM account 
             ^


The above exception was the direct cause of the following exception:

Traceback (most recent call last):
  File "D:\Projects\python\control_system_database_mems\venv\lib\site-packages\flask\app.py", line 2073, in wsgi_app
    response = self.full_dispatch_request()
  File "D:\Projects\python\control_system_database_mems\venv\lib\site-packages\flask\app.py", line 1518, in full_dispatch_request
    rv = self.handle_user_exception(e)
  File "D:\Projects\python\control_system_database_mems\venv\lib\site-packages\flask_restful\__init__.py", line 271, in error_router
    return original_handler(e)
  File "D:\Projects\python\control_system_database_mems\venv\lib\site-packages\flask\app.py", line 1514, in full_dispatch_request
    rv = self.preprocess_request()
  File "D:\Projects\python\control_system_database_mems\venv\lib\site-packages\flask\app.py", line 1857, in preprocess_request
    rv = self.ensure_sync(before_func)()
  File "D:\Projects\python\control_system_database_mems\app\routes.py", line 17, in before_request
    if current_user.is_authenticated:
  File "D:\Projects\python\control_system_database_mems\venv\lib\site-packages\werkzeug\local.py", line 432, in __get__
    obj = instance._get_current_object()
  File "D:\Projects\python\control_system_database_mems\venv\lib\site-packages\werkzeug\local.py", line 554, in _get_current_object
    return self.__local()  # type: ignore
  File "D:\Projects\python\control_system_database_mems\venv\lib\site-packages\flask_login\utils.py", line 26, in <lambda>
    current_user = LocalProxy(lambda: _get_user())
  File "D:\Projects\python\control_system_database_mems\venv\lib\site-packages\flask_login\utils.py", line 346, in _get_user
    current_app.login_manager._load_user()
  File "D:\Projects\python\control_system_database_mems\venv\lib\site-packages\flask_login\login_manager.py", line 318, in _load_user
    user = self._user_callback(user_id)
  File "D:\Projects\python\control_system_database_mems\app\models.py", line 10, in load_user
    return Account.query.get(int(id))
  File "<string>", line 2, in get
  File "D:\Projects\python\control_system_database_mems\venv\lib\site-packages\sqlalchemy\util\deprecations.py", line 401, in warned
    return fn(*args, **kwargs)
  File "D:\Projects\python\control_system_database_mems\venv\lib\site-packages\sqlalchemy\orm\query.py", line 943, in get
    return self._get_impl(ident, loading.load_on_pk_identity)
  File "D:\Projects\python\control_system_database_mems\venv\lib\site-packages\sqlalchemy\orm\query.py", line 947, in _get_impl
    return self.session._get_impl(
  File "D:\Projects\python\control_system_database_mems\venv\lib\site-packages\sqlalchemy\orm\session.py", line 2892, in _get_impl
    return db_load_fn(
  File "D:\Projects\python\control_system_database_mems\venv\lib\site-packages\sqlalchemy\orm\loading.py", line 530, in load_on_pk_identity
    session.execute(
  File "D:\Projects\python\control_system_database_mems\venv\lib\site-packages\sqlalchemy\orm\session.py", line 1692, in execute
    result = conn._execute_20(statement, params or {}, execution_options)
  File "D:\Projects\python\control_system_database_mems\venv\lib\site-packages\sqlalchemy\engine\base.py", line 1614, in _execute_20
    return meth(self, args_10style, kwargs_10style, execution_options)
  File "D:\Projects\python\control_system_database_mems\venv\lib\site-packages\sqlalchemy\sql\elements.py", line 325, in _execute_on_connection
    return connection._execute_clauseelement(
  File "D:\Projects\python\control_system_database_mems\venv\lib\site-packages\sqlalchemy\engine\base.py", line 1481, in _execute_clauseelement
    ret = self._execute_context(
  File "D:\Projects\python\control_system_database_mems\venv\lib\site-packages\sqlalchemy\engine\base.py", line 1845, in _execute_context
    self._handle_dbapi_exception(
  File "D:\Projects\python\control_system_database_mems\venv\lib\site-packages\sqlalchemy\engine\base.py", line 2026, in _handle_dbapi_exception
    util.raise_(
  File "D:\Projects\python\control_system_database_mems\venv\lib\site-packages\sqlalchemy\util\compat.py", line 207, in raise_
    raise exception
  File "D:\Projects\python\control_system_database_mems\venv\lib\site-packages\sqlalchemy\engine\base.py", line 1802, in _execute_context
    self.dialect.do_execute(
  File "D:\Projects\python\control_system_database_mems\venv\lib\site-packages\sqlalchemy\engine\default.py", line 732, in do_execute
    cursor.execute(statement, parameters)
sqlalchemy.exc.ProgrammingError: (psycopg2.errors.UndefinedTable) relation "account" does not exist
LINE 2: FROM account 
             ^

[SQL: SELECT account.id AS account_id, account.username AS account_username, account.email AS account_email, account.password_hash AS account_password_hash, account.date AS account_date, account.avatar AS account_avatar, account.amount AS account_amount, account.last_seen AS account_last_seen, account.uid AS account_uid 
FROM account 
WHERE account.id = %(pk_1)s]
[parameters: {'pk_1': 1}]
(Background on this error at: https://sqlalche.me/e/14/f405)
